Workbook

Sheet Summary
A1: TRIAGE-KE — Budget Summary
A2: AI-Assisted Triage in Kenyan County Referral Hospitals · PI: Joy Owango · SAMPLE / TEST DATA
A4: Category | B4: Year 1 (KES) | C4: Year 2 (KES) | D4: Total (KES) | E4: % of total | F4: Total (USD)
A5: A. Personnel | B5: ='Budget Detail'!K15 -> 12062610 | C5: ='Budget Detail'!L15 -> 4056390 | D5: ='Budget Detail'!I15 -> 16119000 | E5: =IF($D$16=0,0,D5/$D$16) -> 0.59719508 | F5: =D5/Assumptions!$B$7 -> 124953.49
A6: B. Equipment & Software | B6: ='Budget Detail'!K23 -> 1998600 | C6: ='Budget Detail'!L23 -> 446400 | D6: ='Budget Detail'!I23 -> 2445000 | E6: =IF($D$16=0,0,D6/$D$16) -> 0.090585147 | F6: =D6/Assumptions!$B$7 -> 18953.488
A7: C. Travel & Subsistence | B7: ='Budget Detail'!K29 -> 1188000 | C7: ='Budget Detail'!L29 -> 288000 | D7: ='Budget Detail'!I29 -> 1476000 | E7: =IF($D$16=0,0,D7/$D$16) -> 0.05468453 | F7: =D7/Assumptions!$B$7 -> 11441.86
A8: D. Training & Capacity Building | B8: ='Budget Detail'!K35 -> 1116000 | C8: ='Budget Detail'!L35 -> 0 | D8: ='Budget Detail'!I35 -> 1116000 | E8: =IF($D$16=0,0,D8/$D$16) -> 0.04134684 | F8: =D8/Assumptions!$B$7 -> 8651.1628
A9: E. Participant-related Costs | B9: ='Budget Detail'!K41 -> 285000 | C9: ='Budget Detail'!L41 -> 0 | D9: ='Budget Detail'!I41 -> 285000 | E9: =IF($D$16=0,0,D9/$D$16) -> 0.010559005 | F9: =D9/Assumptions!$B$7 -> 2209.3023
A10: F. Ethics, Regulatory & Data Protection | B10: ='Budget Detail'!K47 -> 200000 | C10: ='Budget Detail'!L47 -> 25000 | D10: ='Budget Detail'!I47 -> 225000 | E10: =IF($D$16=0,0,D10/$D$16) -> 0.0083360564 | F10: =D10/Assumptions!$B$7 -> 1744.186
A11: G. Dissemination | B11: ='Budget Detail'!K54 -> 350000 | C11: ='Budget Detail'!L54 -> 1390000 | D11: ='Budget Detail'!I54 -> 1740000 | E11: =IF($D$16=0,0,D11/$D$16) -> 0.064465503 | F11: =D11/Assumptions!$B$7 -> 13488.372
A12: H. Other Direct Costs | B12: ='Budget Detail'!K60 -> 315900 | C12: ='Budget Detail'!L60 -> 164100 | D12: ='Budget Detail'!I60 -> 480000 | E12: =IF($D$16=0,0,D12/$D$16) -> 0.017783587 | F12: =D12/Assumptions!$B$7 -> 3720.9302
A13: Total Direct Costs | B13: =SUM(B5:B12) -> 17516110 | C13: =SUM(C5:C12) -> 6369890 | D13: =SUM(D5:D12) -> 23886000 | E13: =IF($D$16=0,0,D13/$D$16) -> 0.88495575 | F13: =D13/Assumptions!$B$7 -> 185162.79
A14: Contingency | B14: =B13*Assumptions!$B$8 -> 525483.3 | C14: =C13*Assumptions!$B$8 -> 191096.7 | D14: =D13*Assumptions!$B$8 -> 716580 | E14: =IF($D$16=0,0,D14/$D$16) -> 0.026548673 | F14: =D14/Assumptions!$B$7 -> 5554.8837
A15: Indirect costs (institutional overhead) | B15: =B13*Assumptions!$B$6 -> 1751611 | C15: =C13*Assumptions!$B$6 -> 636989 | D15: =D13*Assumptions!$B$6 -> 2388600 | E15: =IF($D$16=0,0,D15/$D$16) -> 0.088495575 | F15: =D15/Assumptions!$B$7 -> 18516.279
A16: GRAND TOTAL | B16: =B13+B14+B15 -> 19793204 | C16: =C13+C14+C15 -> 7197975.7 | D16: =D13+D14+D15 -> 26991180 | E16: =IF($D$16=0,0,D16/$D$16) -> 1 | F16: =D16/Assumptions!$B$7 -> 209233.95
A18: Check: detail direct total minus summary direct total (should be 0) | D18: ='Budget Detail'!I62-D13 -> 0

Sheet Assumptions
A1: TRIAGE-KE Budget — Assumptions
A2: SAMPLE / TEST DATA for HospitiumRIS. Fictional funder, figures illustrative only.
A4: Assumption | B4: Value | C4: Note
A5: Project duration (months) | B5: 18 | C5: Proposal: 25 Oct 2026 – 24 Apr 2028
A6: Indirect cost rate (on direct costs) | B6: 0.1 | C6: Funder cap (fictional HDHIF guidelines)
A7: Exchange rate (KES per USD) | B7: 129 | C7: Planning rate; update as needed
A8: Contingency rate (on direct costs) | B8: 0.03 | C8: Covers price/FX movement
A9: Currency | B9: KES | C9: Kenya Shillings
A11: Legend: blue text on yellow = editable input; black = formula; green = link from another sheet.

Sheet Budget Detail
A1: TRIAGE-KE — Detailed Budget (KES)
A2: PI: Joy Owango · Grant HDHIF/2026/017 · Funder: Hospitium Digital Health Innovation Fund (Demo) · SAMPLE DATA
A4: Code | B4: Category | C4: Line item | D4: Unit | E4: Qty | F4: Unit cost (KES) | G4: Effort / % | H4: Months / Freq | I4: Total (KES) | J4: Year 1 share | K4: Year 1 (KES) | L4: Year 2 (KES) | M4: Justification
A5: A. Personnel
A6: A1 | B6: A. Personnel | C6: Principal Investigator (Joy Owango) | D6: person-month | E6: 1 | F6: 450000 | G6: 0.2 | H6: 18 | I6: =E6*F6*G6*H6 -> 1620000 | J6: 0.67 | K6: =I6*J6 -> 1085400 | L6: =I6-K6 -> 534600 | M6: Overall leadership, stakeholder engagement, reporting
A7: A2 | B7: A. Personnel | C7: Co-I Emergency Medicine (Dr Amani Wekesa) | D7: person-month | E7: 1 | F7: 400000 | G7: 0.15 | H7: 18 | I7: =E7*F7*G7*H7 -> 1080000 | J7: 0.67 | K7: =I7*J7 -> 723600 | L7: =I7-K7 -> 356400 | M7: Clinical lead, reference-standard triage panel
A8: A3 | B8: A. Personnel | C8: Co-I Health Informatics (Dr Faith Chebet) | D8: person-month | E8: 1 | F8: 380000 | G8: 0.2 | H8: 18 | I8: =E8*F8*G8*H8 -> 1368000 | J8: 0.67 | K8: =I8*J8 -> 916560 | L8: =I8-K8 -> 451440 | M8: Tool integration, data pipelines, model monitoring
A9: A4 | B9: A. Personnel | C9: Co-I Biostatistics (Prof Daniel Mbugua) | D9: person-month | E9: 1 | F9: 420000 | G9: 0.1 | H9: 18 | I9: =E9*F9*G9*H9 -> 756000 | J9: 0.5 | K9: =I9*J9 -> 378000 | L9: =I9-K9 -> 378000 | M9: Study design, ITS analysis
A10: A5 | B10: A. Personnel | C10: Co-I Nursing (Ms Grace Kamau) | D10: person-month | E10: 1 | F10: 250000 | G10: 0.15 | H10: 18 | I10: =E10*F10*G10*H10 -> 675000 | J10: 0.67 | K10: =I10*J10 -> 452250 | L10: =I10-K10 -> 222750 | M10: Triage nurse training and fidelity checks
A11: A6 | B11: A. Personnel | C11: Project Coordinator | D11: person-month | E11: 1 | F11: 180000 | G11: 1 | H11: 18 | I11: =E11*F11*G11*H11 -> 3240000 | J11: 0.67 | K11: =I11*J11 -> 2170800 | L11: =I11-K11 -> 1069200 | M11: Day-to-day management across 3 sites
A12: A7 | B12: A. Personnel | C12: Research Assistants (2 per site) | D12: person-month | E12: 6 | F12: 70000 | G12: 1 | H12: 9 | I12: =E12*F12*G12*H12 -> 3780000 | J12: 1 | K12: =I12*J12 -> 3780000 | L12: =I12-K12 -> 0 | M12: Data abstraction & observation, Dec 2026 – Aug 2027
A13: A8 | B13: A. Personnel | C13: Data Manager | D13: person-month | E13: 1 | F13: 200000 | G13: 0.5 | H13: 18 | I13: =E13*F13*G13*H13 -> 1800000 | J13: 0.67 | K13: =I13*J13 -> 1206000 | L13: =I13-K13 -> 594000 | M13: REDCap build, QA, de-identification
A14: A9 | B14: A. Personnel | C14: ML Engineer | D14: person-month | E14: 1 | F14: 300000 | G14: 0.5 | H14: 12 | I14: =E14*F14*G14*H14 -> 1800000 | J14: 0.75 | K14: =I14*J14 -> 1350000 | L14: =I14-K14 -> 450000 | M14: Model calibration, drift monitoring
C15: Subtotal — A. Personnel | I15: =SUM(I6:I14) -> 16119000 | K15: =SUM(K6:K14) -> 12062610 | L15: =SUM(L6:L14) -> 4056390
A17: B. Equipment & Software
A18: B1 | B18: B. Equipment & Software | C18: Ruggedised tablets for triage desks | D18: unit | E18: 9 | F18: 45000 | G18: 1 | H18: 1 | I18: =E18*F18*G18*H18 -> 405000 | J18: 1 | K18: =I18*J18 -> 405000 | L18: =I18-K18 -> 0 | M18: 3 per site; run triage app offline-first
A19: B2 | B19: B. Equipment & Software | C19: Automated vital-signs monitors | D19: unit | E19: 3 | F19: 180000 | G19: 1 | H19: 1 | I19: =E19*F19*G19*H19 -> 540000 | J19: 1 | K19: =I19*J19 -> 540000 | L19: =I19-K19 -> 0 | M19: 1 per site; standardised inputs to model
A20: B3 | B20: B. Equipment & Software | C20: Encrypted analysis laptops | D20: unit | E20: 2 | F20: 120000 | G20: 1 | H20: 1 | I20: =E20*F20*G20*H20 -> 240000 | J20: 1 | K20: =I20*J20 -> 240000 | L20: =I20-K20 -> 0 | M20: Data manager & ML engineer
A21: B4 | B21: B. Equipment & Software | C21: Cloud hosting (in-country region) & backups | D21: month | E21: 1 | F21: 60000 | G21: 1 | H21: 18 | I21: =E21*F21*G21*H21 -> 1080000 | J21: 0.67 | K21: =I21*J21 -> 723600 | L21: =I21-K21 -> 356400 | M21: Kenya Data Protection Act compliant hosting
A22: B5 | B22: B. Equipment & Software | C22: REDCap / survey licences & support | D22: year | E22: 1 | F22: 90000 | G22: 1 | H22: 2 | I22: =E22*F22*G22*H22 -> 180000 | J22: 0.5 | K22: =I22*J22 -> 90000 | L22: =I22-K22 -> 90000 | M22: Annual support fee
C23: Subtotal — B. Equipment & Software | I23: =SUM(I18:I22) -> 2445000 | K23: =SUM(K18:K22) -> 1998600 | L23: =SUM(L18:L22) -> 446400
A25: C. Travel & Subsistence
A26: C1 | B26: C. Travel & Subsistence | C26: Site supervision trips | D26: trip | E26: 3 | F26: 18000 | G26: 1 | H26: 12 | I26: =E26*F26*G26*H26 -> 648000 | J26: 0.75 | K26: =I26*J26 -> 486000 | L26: =I26-K26 -> 162000 | M26: Monthly visit to each site
A27: C2 | B27: C. Travel & Subsistence | C27: Per diem — supervision | D27: night | E27: 3 | F27: 7000 | G27: 2 | H27: 12 | I27: =E27*F27*G27*H27 -> 504000 | J27: 0.75 | K27: =I27*J27 -> 378000 | L27: =I27-K27 -> 126000 | M27: 2 nights per trip
A28: C3 | B28: C. Travel & Subsistence | C28: Research assistant local transport | D28: month | E28: 6 | F28: 6000 | G28: 1 | H28: 9 | I28: =E28*F28*G28*H28 -> 324000 | J28: 1 | K28: =I28*J28 -> 324000 | L28: =I28-K28 -> 0 | M28: Commuting to EDs
C29: Subtotal — C. Travel & Subsistence | I29: =SUM(I26:I28) -> 1476000 | K29: =SUM(K26:K28) -> 1188000 | L29: =SUM(L26:L28) -> 288000
A31: D. Training & Capacity Building
A32: D1 | B32: D. Training & Capacity Building | C32: Clinician training workshop (initial) | D32: workshop | E32: 3 | F32: 250000 | G32: 1 | H32: 1 | I32: =E32*F32*G32*H32 -> 750000 | J32: 1 | K32: =I32*J32 -> 750000 | L32: =I32-K32 -> 0 | M32: 1 per site, ~25 staff each
A33: D2 | B33: D. Training & Capacity Building | C33: Refresher training | D33: workshop | E33: 3 | F33: 90000 | G33: 1 | H33: 1 | I33: =E33*F33*G33*H33 -> 270000 | J33: 1 | K33: =I33*J33 -> 270000 | L33: =I33-K33 -> 0 | M33: Month 4 of implementation
A34: D3 | B34: D. Training & Capacity Building | C34: Good Clinical Practice & data-protection certification | D34: person | E34: 12 | F34: 8000 | G34: 1 | H34: 1 | I34: =E34*F34*G34*H34 -> 96000 | J34: 1 | K34: =I34*J34 -> 96000 | L34: =I34-K34 -> 0 | M34: Study staff
C35: Subtotal — D. Training & Capacity Building | I35: =SUM(I32:I34) -> 1116000 | K35: =SUM(K32:K34) -> 1116000 | L35: =SUM(L32:L34) -> 0
A37: E. Participant-related Costs
A38: E1 | B38: E. Participant-related Costs | C38: Interview participant refreshments & transport | D38: participant | E38: 30 | F38: 1500 | G38: 1 | H38: 1 | I38: =E38*F38*G38*H38 -> 45000 | J38: 1 | K38: =I38*J38 -> 45000 | L38: =I38-K38 -> 0 | M38: Key-informant interviews
A39: E2 | B39: E. Participant-related Costs | C39: Survey participant token | D39: participant | E39: 60 | F39: 1000 | G39: 1 | H39: 1 | I39: =E39*F39*G39*H39 -> 60000 | J39: 1 | K39: =I39*J39 -> 60000 | L39: =I39-K39 -> 0 | M39: Clinician acceptability survey
A40: E3 | B40: E. Participant-related Costs | C40: Interview transcription & translation | D40: interview | E40: 30 | F40: 6000 | G40: 1 | H40: 1 | I40: =E40*F40*G40*H40 -> 180000 | J40: 1 | K40: =I40*J40 -> 180000 | L40: =I40-K40 -> 0 | M40: Kiswahili/English
C41: Subtotal — E. Participant-related Costs | I41: =SUM(I38:I40) -> 285000 | K41: =SUM(K38:K40) -> 285000 | L41: =SUM(L38:L40) -> 0
A43: F. Ethics, Regulatory & Data Protection
A44: F1 | B44: F. Ethics, Regulatory & Data Protection | C44: Ethics review fee (NREIB — Demo) | D44: application | E44: 1 | F44: 50000 | G44: 1 | H44: 1 | I44: =E44*F44*G44*H44 -> 50000 | J44: 1 | K44: =I44*J44 -> 50000 | L44: =I44-K44 -> 0 | M44: Initial review
A45: F2 | B45: F. Ethics, Regulatory & Data Protection | C45: Annual ethics renewal fee | D45: renewal | E45: 1 | F45: 25000 | G45: 1 | H45: 1 | I45: =E45*F45*G45*H45 -> 25000 | J45: 0 | K45: =I45*J45 -> 0 | L45: =I45-K45 -> 25000 | M45: Year 2 continuing review
A46: F3 | B46: F. Ethics, Regulatory & Data Protection | C46: Data Protection Impact Assessment | D46: lump sum | E46: 1 | F46: 150000 | G46: 1 | H46: 1 | I46: =E46*F46*G46*H46 -> 150000 | J46: 1 | K46: =I46*J46 -> 150000 | L46: =I46-K46 -> 0 | M46: External DPIA consultant
...
